2024-07-22 08:49:53,563 INFO: errors [in C:\Users\Make it ready\pythonprojects\assignment\app.py:47]
2024-07-22 08:58:00,486 INFO: errors [in C:\Users\Make it ready\pythonprojects\assignment\app.py:52]
2024-07-22 08:58:13,807 ERROR: Exception on / [GET] [in C:\Python312\Lib\site-packages\flask\app.py:838]
Traceback (most recent call last):
  File "C:\Python312\Lib\site-packages\flask\app.py", line 1473, in wsgi_app
    response = self.full_dispatch_request()
               ^^^^^^^^^^^^^^^^^^^^^^^^^^^^
  File "C:\Python312\Lib\site-packages\flask\app.py", line 882, in full_dispatch_request
    rv = self.handle_user_exception(e)
         ^^^^^^^^^^^^^^^^^^^^^^^^^^^^^
  File "C:\Python312\Lib\site-packages\flask\app.py", line 880, in full_dispatch_request
    rv = self.dispatch_request()
         ^^^^^^^^^^^^^^^^^^^^^^^
  File "C:\Python312\Lib\site-packages\flask\app.py", line 865, in dispatch_request
    return self.ensure_sync(self.view_functions[rule.endpoint])(**view_args)  # type: ignore[no-any-return]
           ^^^^^^^^^^^^^^^^^^^^^^^^^^^^^^^^^^^^^^^^^^^^^^^^^^^^^^^^^^^^^^^^^
  File "C:\Users\Make it ready\pythonprojects\assignment\app.py", line 40, in index
    return render_template('pages/home.html')
           ^^^^^^^^^^^^^^^^^^^^^^^^^^^^^^^^^^
  File "C:\Python312\Lib\site-packages\flask\templating.py", line 150, in render_template
    return _render(app, template, context)
           ^^^^^^^^^^^^^^^^^^^^^^^^^^^^^^^
  File "C:\Python312\Lib\site-packages\flask\templating.py", line 131, in _render
    rv = template.render(context)
         ^^^^^^^^^^^^^^^^^^^^^^^^
  File "C:\Python312\Lib\site-packages\jinja2\environment.py", line 1304, in render
    self.environment.handle_exception()
  File "C:\Python312\Lib\site-packages\jinja2\environment.py", line 939, in handle_exception
    raise rewrite_traceback_stack(source=source)
  File "C:\Users\Make it ready\pythonprojects\assignment\templates\pages\home.html", line 1, in top-level template code
    {% extends 'layouts/main.html' %}
    ^^^^^^^^^^^^^^^^^^^^^^^^^
  File "C:\Python312\Lib\site-packages\flask\templating.py", line 65, in get_source
    return self._get_source_fast(environment, template)
           ^^^^^^^^^^^^^^^^^^^^^^^^^^^^^^^^^^^^^^^^^^^^
  File "C:\Python312\Lib\site-packages\flask\templating.py", line 99, in _get_source_fast
    raise TemplateNotFound(template)
jinja2.exceptions.TemplateNotFound: layouts/main.html
2024-07-22 09:00:13,318 INFO: errors [in C:\Users\Make it ready\pythonprojects\assignment\app.py:52]
2024-07-22 09:00:20,419 ERROR: Exception on / [GET] [in C:\Python312\Lib\site-packages\flask\app.py:838]
Traceback (most recent call last):
  File "C:\Python312\Lib\site-packages\flask\app.py", line 1473, in wsgi_app
    response = self.full_dispatch_request()
               ^^^^^^^^^^^^^^^^^^^^^^^^^^^^
  File "C:\Python312\Lib\site-packages\flask\app.py", line 882, in full_dispatch_request
    rv = self.handle_user_exception(e)
         ^^^^^^^^^^^^^^^^^^^^^^^^^^^^^
  File "C:\Python312\Lib\site-packages\flask\app.py", line 880, in full_dispatch_request
    rv = self.dispatch_request()
         ^^^^^^^^^^^^^^^^^^^^^^^
  File "C:\Python312\Lib\site-packages\flask\app.py", line 865, in dispatch_request
    return self.ensure_sync(self.view_functions[rule.endpoint])(**view_args)  # type: ignore[no-any-return]
           ^^^^^^^^^^^^^^^^^^^^^^^^^^^^^^^^^^^^^^^^^^^^^^^^^^^^^^^^^^^^^^^^^
  File "C:\Users\Make it ready\pythonprojects\assignment\app.py", line 40, in index
    return render_template('pages/home.html')
           ^^^^^^^^^^^^^^^^^^^^^^^^^^^^^^^^^^
  File "C:\Python312\Lib\site-packages\flask\templating.py", line 150, in render_template
    return _render(app, template, context)
           ^^^^^^^^^^^^^^^^^^^^^^^^^^^^^^^
  File "C:\Python312\Lib\site-packages\flask\templating.py", line 131, in _render
    rv = template.render(context)
         ^^^^^^^^^^^^^^^^^^^^^^^^
  File "C:\Python312\Lib\site-packages\jinja2\environment.py", line 1304, in render
    self.environment.handle_exception()
  File "C:\Python312\Lib\site-packages\jinja2\environment.py", line 939, in handle_exception
    raise rewrite_traceback_stack(source=source)
  File "C:\Users\Make it ready\pythonprojects\assignment\templates\pages\home.html", line 1, in top-level template code
    {% extends 'layouts/main.html' %}
    ^^^^^^^^^^^^^^^^^^^^^^^^^
  File "C:\Users\Make it ready\pythonprojects\assignment\templates\layouts\main.html", line 83, in top-level template code
    <li {% if request.endpoint == 'venues' %} class="active" {% endif %}><a href="{{ url_for('venues') }}">Venues</a></li>
    ^^^^^^^^^^^^^^^^^^^^^^^^^
  File "C:\Python312\Lib\site-packages\flask\app.py", line 1084, in url_for
    return self.handle_url_build_error(error, endpoint, values)
           ^^^^^^^^^^^^^^^^^^^^^^^^^^^^^^^^^^^^^^^^^^^^^^^^^^^^
  File "C:\Python312\Lib\site-packages\flask\app.py", line 1073, in url_for
    rv = url_adapter.build(  # type: ignore[union-attr]
         ^^^^^^^^^^^^^^^^^^^^^^^^^^^^^^^^^^^^^^^^^^^^^^
  File "C:\Python312\Lib\site-packages\werkzeug\routing\map.py", line 924, in build
    raise BuildError(endpoint, values, method, self)
werkzeug.routing.exceptions.BuildError: Could not build url for endpoint 'venues'. Did you mean 'index' instead?
2024-07-22 09:06:43,780 INFO: errors [in C:\Users\Make it ready\pythonprojects\assignment\app.py:52]
2024-07-22 09:06:52,506 ERROR: Exception on / [GET] [in C:\Python312\Lib\site-packages\flask\app.py:838]
Traceback (most recent call last):
  File "C:\Python312\Lib\site-packages\flask\app.py", line 1473, in wsgi_app
    response = self.full_dispatch_request()
               ^^^^^^^^^^^^^^^^^^^^^^^^^^^^
  File "C:\Python312\Lib\site-packages\flask\app.py", line 882, in full_dispatch_request
    rv = self.handle_user_exception(e)
         ^^^^^^^^^^^^^^^^^^^^^^^^^^^^^
  File "C:\Python312\Lib\site-packages\flask\app.py", line 880, in full_dispatch_request
    rv = self.dispatch_request()
         ^^^^^^^^^^^^^^^^^^^^^^^
  File "C:\Python312\Lib\site-packages\flask\app.py", line 865, in dispatch_request
    return self.ensure_sync(self.view_functions[rule.endpoint])(**view_args)  # type: ignore[no-any-return]
           ^^^^^^^^^^^^^^^^^^^^^^^^^^^^^^^^^^^^^^^^^^^^^^^^^^^^^^^^^^^^^^^^^
  File "C:\Users\Make it ready\pythonprojects\assignment\app.py", line 40, in index
    return render_template('pages/home.html')
           ^^^^^^^^^^^^^^^^^^^^^^^^^^^^^^^^^^
  File "C:\Python312\Lib\site-packages\flask\templating.py", line 150, in render_template
    return _render(app, template, context)
           ^^^^^^^^^^^^^^^^^^^^^^^^^^^^^^^
  File "C:\Python312\Lib\site-packages\flask\templating.py", line 131, in _render
    rv = template.render(context)
         ^^^^^^^^^^^^^^^^^^^^^^^^
  File "C:\Python312\Lib\site-packages\jinja2\environment.py", line 1304, in render
    self.environment.handle_exception()
  File "C:\Python312\Lib\site-packages\jinja2\environment.py", line 939, in handle_exception
    raise rewrite_traceback_stack(source=source)
  File "C:\Users\Make it ready\pythonprojects\assignment\templates\pages\home.html", line 1, in top-level template code
    {% extends 'layouts/main.html' %}
    ^^^^^^^^^^^^^^^^^^^^^^^^^
  File "C:\Users\Make it ready\pythonprojects\assignment\templates\layouts\main.html", line 84, in top-level template code
    <li {% if request.endpoint == 'venues' %} class="active" {% endif %}><a href="{{ url_for('venues') }}">Venues</a></li>
    ^^^^^^^^^^^^^^^^^^^^^^^^^
  File "C:\Python312\Lib\site-packages\flask\app.py", line 1084, in url_for
    return self.handle_url_build_error(error, endpoint, values)
           ^^^^^^^^^^^^^^^^^^^^^^^^^^^^^^^^^^^^^^^^^^^^^^^^^^^^
  File "C:\Python312\Lib\site-packages\flask\app.py", line 1073, in url_for
    rv = url_adapter.build(  # type: ignore[union-attr]
         ^^^^^^^^^^^^^^^^^^^^^^^^^^^^^^^^^^^^^^^^^^^^^^
  File "C:\Python312\Lib\site-packages\werkzeug\routing\map.py", line 924, in build
    raise BuildError(endpoint, values, method, self)
werkzeug.routing.exceptions.BuildError: Could not build url for endpoint 'venues'. Did you mean 'index' instead?
2024-07-22 09:10:13,297 INFO: errors [in C:\Users\Make it ready\pythonprojects\assignment\app.py:52]
2024-07-22 09:19:25,053 ERROR: Exception on /add [POST] [in C:\Python312\Lib\site-packages\flask\app.py:838]
Traceback (most recent call last):
  File "C:\Users\Make it ready\pythonprojects\assignment\app.py", line 31, in add_user_data
    flash('Data was successfully listed!')
  File "C:\Python312\Lib\site-packages\flask\helpers.py", line 323, in flash
    session["_flashes"] = flashes
    ~~~~~~~^^^^^^^^^^^^
  File "C:\Python312\Lib\site-packages\flask\sessions.py", line 102, in _fail
    raise RuntimeError(
RuntimeError: The session is unavailable because no secret key was set.  Set the secret_key on the application to something unique and secret.

During handling of the above exception, another exception occurred:

Traceback (most recent call last):
  File "C:\Python312\Lib\site-packages\flask\app.py", line 1473, in wsgi_app
    response = self.full_dispatch_request()
               ^^^^^^^^^^^^^^^^^^^^^^^^^^^^
  File "C:\Python312\Lib\site-packages\flask\app.py", line 882, in full_dispatch_request
    rv = self.handle_user_exception(e)
         ^^^^^^^^^^^^^^^^^^^^^^^^^^^^^
  File "C:\Python312\Lib\site-packages\flask\app.py", line 880, in full_dispatch_request
    rv = self.dispatch_request()
         ^^^^^^^^^^^^^^^^^^^^^^^
  File "C:\Python312\Lib\site-packages\flask\app.py", line 865, in dispatch_request
    return self.ensure_sync(self.view_functions[rule.endpoint])(**view_args)  # type: ignore[no-any-return]
           ^^^^^^^^^^^^^^^^^^^^^^^^^^^^^^^^^^^^^^^^^^^^^^^^^^^^^^^^^^^^^^^^^
  File "C:\Users\Make it ready\pythonprojects\assignment\app.py", line 34, in add_user_data
    flash('An error occurred. Data could not be listed')
  File "C:\Python312\Lib\site-packages\flask\helpers.py", line 323, in flash
    session["_flashes"] = flashes
    ~~~~~~~^^^^^^^^^^^^
  File "C:\Python312\Lib\site-packages\flask\sessions.py", line 102, in _fail
    raise RuntimeError(
RuntimeError: The session is unavailable because no secret key was set.  Set the secret_key on the application to something unique and secret.
2024-07-22 09:25:45,507 INFO: errors [in C:\Users\Make it ready\pythonprojects\assignment\app.py:54]
2024-07-22 09:25:53,120 ERROR: Exception on /add [POST] [in C:\Python312\Lib\site-packages\flask\app.py:838]
Traceback (most recent call last):
  File "C:\Python312\Lib\site-packages\flask\app.py", line 1473, in wsgi_app
    response = self.full_dispatch_request()
               ^^^^^^^^^^^^^^^^^^^^^^^^^^^^
  File "C:\Python312\Lib\site-packages\flask\app.py", line 883, in full_dispatch_request
    return self.finalize_request(rv)
           ^^^^^^^^^^^^^^^^^^^^^^^^^
  File "C:\Python312\Lib\site-packages\flask\app.py", line 902, in finalize_request
    response = self.make_response(rv)
               ^^^^^^^^^^^^^^^^^^^^^^
  File "C:\Python312\Lib\site-packages\flask\app.py", line 1174, in make_response
    raise TypeError(
TypeError: The view function for 'add_user_data' did not return a valid response. The function either returned None or ended without a return statement.
2024-07-22 09:38:54,451 INFO: errors [in C:\Users\Make it ready\pythonprojects\assignment\app.py:53]
2024-07-22 09:54:05,878 INFO: errors [in C:\Users\Make it ready\pythonprojects\assignment\app.py:53]
